<?xml version="1.0"?>
<robot xmlns:xacro="http://www.ros.org/wiki/xacro">

<xacro:include filename="inertial_macros.xacro" />


<material name="black">
<color rgba="0 0 0 1"/>
</material>
<material name="blue">
<color rgba="0.2 0.2 1 1"/>
</material>
<material name="white">
<color rgba="1 1 1 1"/>
</material>

<!-- BASE LINK -->

<link name="base_link">
</link>


<!-- NAVI LINK -->
<joint name="navi_joint" type="fixed">
<parent link="base_link"/>
<child link="navi"/>
<origin xyz="-0.225 0 0"/>
</joint>

<link name="navi">
   <visual>
        <origin xyz="0.225 0 0.05"/>
        <material name="black"/>
        <geometry>
            <box size="0.45 0.5 0.1"/>
        </geometry>
   </visual>
   <collision>
        <origin xyz="0.225 0 0.05"/>
        <geometry>
            <box size="0.45 0.5 0.1"/>
        </geometry>
   </collision>
   <xacro:inertial_box mass="15" x="0.45" y="0.5" z="0.1">
    <origin xyz="0.225 0 0.05" rpy="0 0 0"/>
   </xacro:inertial_box>
</link>

<!-- LEFT WHEEL LINK -->
<joint name="left_wheel_joint" type="continuous">
    <parent link="base_link"/>
    <child link="left_wheel"/>
    <origin xyz="0 0.30 0" rpy="-${pi/2} 0 0"/>
    <axis xyz="0 0 1"/>

</joint>

<link name="left_wheel">
    <visual>
        <geometry>
            <cylinder radius="0.085" length="0.07"/>
        </geometry>
        <material name="white"/>
    </visual>
    <collision>
        <geometry>
            <cylinder radius="0.085" length="0.07"/>
        </geometry>
    </collision>
    <xacro:inertial_cylinder mass="4" length="0.07" radius="0.085">
        <origin xyz="0 0 0" rpy="0 0 0"/>
    </xacro:inertial_cylinder>
</link>

<!-- RIGHT WHEEL LINK -->
<joint name="right_wheel_joint" type="continuous">
    <parent link="base_link"/>
    <child link="right_wheel"/>
    <origin xyz="0 -0.30 0" rpy="${pi/2} 0 0"/>
    <axis xyz="0 0 -1"/>

</joint>

<link name="right_wheel">
    <visual>
        <geometry>
            <cylinder radius="0.085" length="0.07"/>
        </geometry>
        <material name="white"/>
    </visual>

    <collision>
        <geometry>
            <cylinder radius="0.085" length="0.07"/>
        </geometry>
    </collision>
    <xacro:inertial_cylinder mass="4" length="0.07" radius="0.085">
        <origin xyz="0 0 0" rpy="0 0 0"/>
    </xacro:inertial_cylinder>
</link>


<!-- CASTER WHEEL LINK -->
<joint name="caster_wheel_joint" type="fixed">
    <parent link="navi"/>
    <child link="caster_wheel"/>
    <origin xyz="0.40 0 0"/>
</joint>

<link name="caster_wheel">
    <visual>
        <geometry>
            <sphere radius="0.0825"/>
        </geometry>
        <material name="white"/>
    </visual>
    <collision>
        <geometry>
            <sphere radius="0.0825"/>
        </geometry>
    </collision>
    <xacro:inertial_sphere mass="0.2" radius="0.085">
        <origin xyz="0 0 0" rpy="0 0 0"/>
    </xacro:inertial_sphere>
</link>


</robot>